Workbook

Sheet experiment_data
A1: user_id | B1: signup_date | C1: experiment_group | D1: region | E1: device_type | F1: traffic_source | G1: plan_type | H1: visited_landing_page | I1: started_trial | J1: completed_onboarding | K1: converted_to_paid | L1: revenue_30d | M1: support_tickets_30d | N1: refund_requested | O1: days_to_convert | P1: engagement_score | Q1: control_converted | R1: treatment_converted
A2: USR-100001 | B2: 45732 | C2: Control | D2: North | E2: Desktop | F2: Email | G2: Basic | H2: 0 | I2: 0 | J2: 0 | K2: 0 | L2: 0 | M2: 0 | N2: 0 | P2: 45.7 | Q2: =IF(C2="Control",K2,"") -> 0 | R2: =IF(C2="Treatment",K2,"")
A3: USR-100002 | B3: 45724 | C3: Control | D3: West | E3: Mobile | F3: Organic | G3: Free | H3: 1 | I3: 0 | J3: 0 | K3: 0 | L3: 0 | M3: 0 | N3: 0 | P3: 48.6 | Q3: =IF(C3="Control",K3,"") -> 0 | R3: =IF(C3="Treatment",K3,"")
A4: USR-100003 | B4: 45771 | C4: Control | D4: East | E4: Mobile | F4: Paid Search | G4: Premium | H4: 1 | I4: 0 | J4: 0 | K4: 0 | L4: 0 | M4: 1 | N4: 0 | P4: 35.4 | Q4: =IF(C4="Control",K4,"") -> 0 | R4: =IF(C4="Treatment",K4,"")
A5: USR-100004 | B5: 45781 | C5: Control | D5: South | E5: Mobile | F5: Email | G5: Basic | H5: 1 | I5: 0 | J5: 0 | K5: 0 | L5: 0 | M5: 0 | N5: 0 | P5: 64.6 | Q5: =IF(C5="Control",K5,"") -> 0 | R5: =IF(C5="Treatment",K5,"")
A6: USR-100005 | B6: 45700 | C6: Control | D6: North | E6: Tablet | F6: Organic | G6: Free | H6: 0 | I6: 0 | J6: 0 | K6: 0 | L6: 0 | M6: 0 | N6: 0 | P6: 66.6 | Q6: =IF(C6="Control",K6,"") -> 0 | R6: =IF(C6="Treatment",K6,"")
A7: USR-100006 | B7: 45685 | C7: Control | D7: East | E7: Mobile | F7: Organic | G7: Premium | H7: 1 | I7: 0 | J7: 0 | K7: 0 | L7: 0 | M7: 0 | N7: 0 | P7: 40.8 | Q7: =IF(C7="Control",K7,"") -> 0 | R7: =IF(C7="Treatment",K7,"")
A8: USR-100007 | B8: 45755 | C8: Control | D8: East | E8: Mobile | F8: Paid Search | G8: Basic | H8: 1 | I8: 1 | J8: 0 | K8: 0 | L8: 0 | M8: 0 | N8: 0 | P8: 57.1 | Q8: =IF(C8="Control",K8,"") -> 0 | R8: =IF(C8="Treatment",K8,"")
A9: USR-100008 | B9: 45794 | C9: Control | D9: South | E9: Mobile | F9: Paid Search | G9: Free | H9: 0 | I9: 0 | J9: 0 | K9: 0 | L9: 0 | M9: 0 | N9: 0 | P9: 36.4 | Q9: =IF(C9="Control",K9,"") -> 0 | R9: =IF(C9="Treatment",K9,"")
A10: USR-100009 | B10: 45711 | C10: Control | D10: South | E10: Tablet | F10: Referral | G10: Basic | H10: 0 | I10: 0 | J10: 0 | K10: 0 | L10: 0 | M10: 0 | N10: 0 | P10: 55.4 | Q10: =IF(C10="Control",K10,"") -> 0 | R10: =IF(C10="Treatment",K10,"")
A11: USR-100010 | B11: 45806 | C11: Control | D11: West | E11: Desktop | F11: Social | G11: Free | H11: 1 | I11: 0 | J11: 0 | K11: 0 | L11: 0 | M11: 0 | N11: 0 | P11: 57.3 | Q11: =IF(C11="Control",K11,"") -> 0 | R11: =IF(C11="Treatment",K11,"")
A12: USR-100011 | B12: 45777 | C12: Control | D12: East | E12: Mobile | F12: Paid Search | G12: Basic | H12: 1 | I12: 1 | J12: 1 | K12: 0 | L12: 0 | M12: 0 | N12: 0 | P12: 63.6 | Q12: =IF(C12="Control",K12,"") -> 0 | R12: =IF(C12="Treatment",K12,"")
A13: USR-100012 | B13: 45732 | C13: Control | D13: East | E13: Mobile | F13: Social | G13: Premium | H13: 1 | I13: 1 | J13: 1 | K13: 0 | L13: 0 | M13: 1 | N13: 0 | P13: 80.4 | Q13: =IF(C13="Control",K13,"") -> 0 | R13: =IF(C13="Treatment",K13,"")
... A60: USR-100059 | B60: 45761 | C60: Control | D60: North | E60: Mobile | F60: Social | G60: Free | H60: 0 | I60: 0 | J60: 0 | K60: 0 | L60: 0 | M60: 2 | N60: 0 | P60: 48.9 | Q60: =IF(C60="Control",K60,"") -> 0 | R60: =IF(C60="Treatment",K60,"")
A61: USR-100060 | B61: 45658 | C61: Control | D61: West | E61: Mobile | F61: Social | G61: Free | H61: 1 | I61: 1 | J61: 1 | K61: 1 | L61: 240.42 | M61: 0 | N61: 0 | O61: 16 | P61: 56.5 | Q61: =IF(C61="Control",K61,"") -> 1 | R61: =IF(C61="Treatment",K61,"")
A62: USR-100061 | B62: 45749 | C62: Control | D62: South | E62: Mobile | F62: Referral | G62: Free | H62: 1 | I62: 0 | J62: 0 | K62: 0 | L62: 0 | M62: 0 | N62: 0 | P62: 53.7 | Q62: =IF(C62="Control",K62,"") -> 0 | R62: =IF(C62="Treatment",K62,"")
A63: USR-100062 | B63: 45745 | C63: Control | D63: North | E63: Mobile | F63: Social | G63: Premium | H63: 0 | I63: 0 | J63: 0 | K63: 0 | L63: 0 | M63: 0 | N63: 0 | P63: 62.2 | Q63: =IF(C63="Control",K63,"") -> 0 | R63: =IF(C63="Treatment",K63,"")
A64: USR-100063 | B64: 45792 | C64: Control | D64: South | E64: Desktop | F64: Organic | G64: Free | H64: 1 | I64: 0 | J64: 0 | K64: 0 | L64: 0 | M64: 0 | N64: 0 | P64: 50.2 | Q64: =IF(C64="Control",K64,"") -> 0 | R64: =IF(C64="Treatment",K64,"")
A65: USR-100064 | B65: 45758 | C65: Control | D65: North | E65: Mobile | F65: Organic | G65: Basic | H65: 1 | I65: 0 | J65: 0 | K65: 0 | L65: 0 | M65: 0 | N65: 0 | P65: 74.3 | Q65: =IF(C65="Control",K65,"") -> 0 | R65: =IF(C65="Treatment",K65,"")
A66: USR-100065 | B66: 45723 | C66: Control | D66: South | E66: Desktop | F66: Paid Search | G66: Free | H66: 1 | I66: 0 | J66: 0 | K66: 0 | L66: 0 | M66: 0 | N66: 0 | P66: 58 | Q66: =IF(C66="Control",K66,"") -> 0 | R66: =IF(C66="Treatment",K66,"")
A67: USR-100066 | B67: 45807 | C67: Control | D67: South | E67: Mobile | F67: Organic | G67: Free | H67: 0 | I67: 0 | J67: 0 | K67: 0 | L67: 0 | M67: 0 | N67: 0 | P67: 46.7 | Q67: =IF(C67="Control",K67,"") -> 0 | R67: =IF(C67="Treatment",K67,"")
A68: USR-100067 | B68: 45664 | C68: Control | D68: South | E68: Desktop | F68: Organic | G68: Premium | H68: 1 | I68: 0 | J68: 0 | K68: 0 | L68: 0 | M68: 1 | N68: 0 | P68: 49.6 | Q68: =IF(C68="Control",K68,"") -> 0 | R68: =IF(C68="Treatment",K68,"")
A69: USR-100068 | B69: 45785 | C69: Control | D69: West | E69: Mobile | F69: Social | G69: Free | H69: 0 | I69: 0 | J69: 0 | K69: 0 | L69: 0 | M69: 0 | N69: 0 | P69: 60.4 | Q69: =IF(C69="Control",K69,"") -> 0 | R69: =IF(C69="Treatment",K69,"")
A70: USR-100069 | B70: 45735 | C70: Control | D70: East | E70: Desktop | F70: Email | G70: Free | H70: 1 | I70: 1 | J70: 1 | K70: 0 | L70: 0 | M70: 0 | N70: 0 | P70: 55.3 | Q70: =IF(C70="Control",K70,"") -> 0 | R70: =IF(C70="Treatment",K70,"")
A71: USR-100070 | B71: 45793 | C71: Control | D71: North | E71: Desktop | F71: Organic | G71: Free | H71: 0 | I71: 0 | J71: 0 | K71: 0 | L71: 0 | M71: 0 | N71: 0 | P71: 56.2 | Q71: =IF(C71="Control",K71,"") -> 0 | R71: =IF(C71="Treatment",K71,"")
A72: USR-100071 | B72: 45724 | C72: Control | D72: West | E72: Mobile | F72: Email | G72: Free | H72: 0 | I72: 0 | J72: 0 | K72: 0 | L72: 0 | M72: 0 | N72: 0 | P72: 29.4 | Q72: =IF(C72="Control",K72,"") -> 0 | R72: =IF(C72="Treatment",K72,"")
A73: USR-100072 | B73: 45724 | C73: Control | D73: East | E73: Mobile | F73: Email | G73: Free | H73: 1 | I73: 0 | J73: 0 | K73: 0 | L73: 0 | M73: 0 | N73: 0 | P73: 54.2 | Q73: =IF(C73="Control",K73,"") -> 0 | R73: =IF(C73="Treatment",K73,"")
... A79: USR-100078 | B79: 45673 | C79: Control | D79: North | E79: Mobile | F79: Organic | G79: Free | H79: 0 | I79: 0 | J79: 0 | K79: 0 | L79: 0 | M79: 2 | N79: 0 | P79: 48.4 | Q79: =IF(C79="Control",K79,"") -> 0 | R79: =IF(C79="Treatment",K79,"")
A80: USR-100079 | B80: 45708 | C80: Control | D80: West | E80: Desktop | F80: Organic | G80: Free | H80: 1 | I80: 1 | J80: 1 | K80: 1 | L80: 457.51 | M80: 0 | N80: 0 | O80: 7 | P80: 38 | Q80: =IF(C80="Control",K80,"") -> 1 | R80: =IF(C80="Treatment",K80,"")
A81: USR-100080 | B81: 45798 | C81: Control | D81: East | E81: Mobile | F81: Social | G81: Free | H81: 1 | I81: 0 | J81: 0 | K81: 0 | L81: 0 | M81: 0 | N81: 0 | P81: 44.2 | Q81: =IF(C81="Control",K81,"") -> 0 | R81: =IF(C81="Treatment",K81,"")
A82: USR-100081 | B82: 45785 | C82: Control | D82: South | E82: Mobile | F82: Organic | G82: Free | H82: 1 | I82: 1 | J82: 1 | K82: 0 | L82: 0 | M82: 0 | N82: 0 | P82: 81.2 | Q82: =IF(C82="Control",K82,"") -> 0 | R82: =IF(C82="Treatment",K82,"")
A83: USR-100082 | B83: 45724 | C83: Control | D83: South | E83: Mobile | F83: Referral | G83: Free | H83: 1 | I83: 1 | J83: 0 | K83: 0 | L83: 0 | M83: 0 | N83: 0 | P83: 63.8 | Q83: =IF(C83="Control",K83,"") -> 0 | R83: =IF(C83="Treatment",K83,"")
A84: USR-100083 | B84: 45748 | C84: Control | D84: South | E84: Desktop | F84: Email | G84: Free | H84: 0 | I84: 0 | J84: 0 | K84: 0 | L84: 0 | M84: 0 | N84: 0 | P84: 64.7 | Q84: =IF(C84="Control",K84,"") -> 0 | R84: =IF(C84="Treatment",K84,"")
A85: USR-100084 | B85: 45719 | C85: Control | D85: West | E85: Mobile | F85: Social | G85: Basic | H85: 0 | I85: 0 | J85: 0 | K85: 0 | L85: 0 | M85: 0 | N85: 0 | P85: 60.4 | Q85: =IF(C85="Control",K85,"") -> 0 | R85: =IF(C85="Treatment",K85,"")
A86: USR-100085 | B86: 45763 | C86: Control | D86: South | E86: Mobile | F86: Paid Search | G86: Free | H86: 0 | I86: 0 | J86: 0 | K86: 0 | L86: 0 | M86: 0 | N86: 0 | P86: 66.6 | Q86: =IF(C86="Control",K86,"") -> 0 | R86: =IF(C86="Treatment",K86,"")
A87: USR-100086 | B87: 45666 | C87: Control | D87: North | E87: Desktop | F87: Organic | G87: Free | H87: 1 | I87: 0 | J87: 0 | K87: 0 | L87: 0 | M87: 0 | N87: 0 | P87: 50.9 | Q87: =IF(C87="Control",K87,"") -> 0 | R87: =IF(C87="Treatment",K87,"")
A88: USR-100087 | B88: 45679 | C88: Control | D88: West | E88: Desktop | F88: Social | G88: Basic | H88: 0 | I88: 0 | J88: 0 | K88: 0 | L88: 0 | M88: 0 | N88: 0 | P88: 51 | Q88: =IF(C88="Control",K88,"") -> 0 | R88: =IF(C88="Treatment",K88,"")
A89: USR-100088 | B89: 45777 | C89: Control | D89: South | E89: Mobile | F89: Email | G89: Premium | H89: 0 | I89: 0 | J89: 0 | K89: 0 | L89: 0 | M89: 0 | N89: 0 | P89: 65.8 | Q89: =IF(C89="Control",K89,"") -> 0 | R89: =IF(C89="Treatment",K89,"")
A90: USR-100089 | B90: 45772 | C90: Control | D90: North | E90: Mobile | F90: Referral | G90: Basic | H90: 1 | I90: 0 | J90: 0 | K90: 0 | L90: 0 | M90: 0 | N90: 0 | P90: 61.8 | Q90: =IF(C90="Control",K90,"") -> 0 | R90: =IF(C90="Treatment",K90,"")
A91: USR-100090 | B91: 45689 | C91: Control | D91: North | E91: Mobile | F91: Organic | G91: Basic | H91: 1 | I91: 0 | J91: 0 | K91: 0 | L91: 0 | M91: 0 | N91: 0 | P91: 54.5 | Q91: =IF(C91="Control",K91,"") -> 0 | R91: =IF(C91="Treatment",K91,"")
...

Sheet summary
A1: Experiment Summary
A3: Metric | B3: Control | C3: Treatment
A4: User Count | B4: =COUNTIFS(experiment_data!C2:C1409,"Control") -> 690 | C4: =COUNTIFS(experiment_data!C2:C1409,"Treatment") -> 710
A5: Landing Page Visit Rate | B5: =COUNTIFS(experiment_data!C2:C1409,"Control",experiment_data!H2:H1409,1)/[1]experiment_summary!B4 -> 0.63623188 | C5: =COUNTIFS(experiment_data!C:C,"Treatment",experiment_data!H:H,1)/C4 -> 0.72394366
A6: Trial Start Rate | B6: =COUNTIFS(experiment_data!C:C,"Control",experiment_data!I:I,1)/B4 -> 0.25072464 | C6: =COUNTIFS(experiment_data!C:C,"Treatment",experiment_data!I:I,1)/C4 -> 0.29014085
A7: Onboarding Completion Rate | B7: =COUNTIFS(experiment_data!C:C,"Control",experiment_data!J:J,1)/B4 -> 0.15652174 | C7: =COUNTIFS(experiment_data!C:C,"Treatment",experiment_data!J:J,1)/C4 -> 0.21126761
A8: Paid Conversion Rate | B8: =COUNTIFS(experiment_data!C:C,"Control",experiment_data!K:K,1)/B4 -> 0.031884058 | C8: =COUNTIFS(experiment_data!C:C,"Treatment",experiment_data!K:K,1)/C4 -> 0.070422535
A9: Avg Revenue Per User | B9: =SUMIF(experiment_data!C:C,"Control",experiment_data!L:L)/B4 -> 51.974319 | C9: =SUMIF(experiment_data!C:C,"Treatment",experiment_data!L:L)/C4 -> 54.254521
A10: Avg Revenue Per Converted User | B10: =SUMIF(experiment_data!C:C,"Control",experiment_data!L:L)/COUNTIFS(experiment_data!C:C,"Control",experiment_data!K:K,1) -> 1630.1036 | C10: =SUMIF(experiment_data!C:C,"Treatment",experiment_data!L:L)/COUNTIFS(experiment_data!C:C,"Treatment",experiment_data!K:K,1) -> 770.4142
A11: Refund Rate | B11: =COUNTIFS(experiment_data!C:C,"Control",experiment_data!N:N,1)/B4 -> 0 | C11: =COUNTIFS(experiment_data!C:C,"Treatment",experiment_data!N:N,1)/C4 -> 0.0042253521
A12: Support Ticket Rate | B12: =COUNTIFS(experiment_data!C:C,"Control",experiment_data!M:M,">"&0)/B4 -> 0.14782609 | C12: =COUNTIFS(experiment_data!C:C,"Treatment",experiment_data!M:M,">"&0)/C4 -> 0.24788732
A13: Avg Engagement Score | B13: =AVERAGEIF(experiment_data!C:C,"Control",experiment_data!P:P) -> 57.029532 | C13: =AVERAGEIF(experiment_data!C:C,"Treatment",experiment_data!P:P) -> 62.940028
A14: Avg Days to Convert | B14: =AVERAGEIFS(experiment_data!O:O,experiment_data!C:C,"Control",experiment_data!K:K,1) -> 8.8636364 | C14: =AVERAGEIFS(experiment_data!O:O,experiment_data!C:C,"Treatment",experiment_data!K:K,1) -> 6.4
A17: Segment Analysis
A18: Paid Conversion Rate by Region | F18: Paid Conversion Rate by Device Type | K18: Paid Conversion Rate by Traffic Source | P18: Paid Conversion Rate by Plan Type
A20: Region | B20: Control | C20: Treatment | F20: Device Type | G20: Control | H20: Treatment | K20: Traffic Source | L20: Control | M20: Treatment | P20: Plan Type | Q20: Control | R20: Treatment
A21: North | B21: =COUNTIFS(experiment_data!C:C,"Control",experiment_data!D:D,"North",experiment_data!K:K,1)/COUNTIFS(experiment_data!C:C,"Control",experiment_data!D:D,"North") -> 0.034825871 | C21: =COUNTIFS(experiment_data!C:C,"Treatment",experiment_data!D:D,"North",experiment_data!K:K,1)/COUNTIFS(experiment_data!C:C,"Treatment",experiment_data!D:D,"North") -> 0.088888889 | F21: Mobile | G21: =COUNTIFS(experiment_data!C:C,"Control",experiment_data!E:E,"Mobile",experiment_data!K:K,1)/COUNTIFS(experiment_data!C:C,"Control",experiment_data!E:E,"Mobile") -> 0.025821596 | H21: =COUNTIFS(experiment_data!C:C,"Treatment",experiment_data!E:E,"Mobile",experiment_data!K:K,1)/COUNTIFS(experiment_data!C:C,"Treatment",experiment_data!E:E,"Mobile") -> 0.074074074 | K21: Organic | L21: =COUNTIFS(experiment_data!C:C,"Control",experiment_data!F:F,"Organic",experiment_data!K:K,1)/COUNTIFS(experiment_data!C:C,"Control",experiment_data!F:F,"Organic") -> 0.020325203 | M21: =COUNTIFS(experiment_data!C:C,"Treatment",experiment_data!F:F,"Organic",experiment_data!K:K,1)/COUNTIFS(experiment_data!C:C,"Treatment",experiment_data!F:F,"Organic") -> 0.063291139 | P21: Free | Q21: =COUNTIFS(experiment_data!C:C,"Control",experiment_data!G:G,"Free",experiment_data!K:K,1)/COUNTIFS(experiment_data!C:C,"Control",experiment_data!G:G,"Free") -> 0.030555556 | R21: =COUNTIFS(experiment_data!C:C,"Treatment",experiment_data!G:G,"Free",experiment_data!K:K,1)/COUNTIFS(experiment_data!C:C,"Treatment",experiment_data!G:G,"Free") -> 0.092896175
A22: South | B22: =COUNTIFS(experiment_data!C:C,"Control",experiment_data!D:D,"South",experiment_data!K:K,1)/COUNTIFS(experiment_data!C:C,"Control",experiment_data!D:D,"South") -> 0.032608696 | C22: =COUNTIFS(experiment_data!C:C,"Treatment",experiment_data!D:D,"South",experiment_data!K:K,1)/COUNTIFS(experiment_data!C:C,"Treatment",experiment_data!D:D,"South") -> 0.076502732 | F22: Desktop | G22: =COUNTIFS(experiment_data!C:C,"Control",experiment_data!E:E,"Desktop",experiment_data!K:K,1)/COUNTIFS(experiment_data!C:C,"Control",experiment_data!E:E,"Desktop") -> 0.045 | H22: =COUNTIFS(experiment_data!C:C,"Treatment",experiment_data!E:E,"Desktop",experiment_data!K:K,1)/COUNTIFS(experiment_data!C:C,"Treatment",experiment_data!E:E,"Desktop") -> 0.0657277 | K22: Paid Search | L22: =COUNTIFS(experiment_data!C:C,"Control",experiment_data!F:F,"Paid Search",experiment_data!K:K,1)/COUNTIFS(experiment_data!C:C,"Control",experiment_data!F:F,"Paid Search") -> 0.012903226 | M22: =COUNTIFS(experiment_data!C:C,"Treatment",experiment_data!F:F,"Paid Search",experiment_data!K:K,1)/COUNTIFS(experiment_data!C:C,"Treatment",experiment_data!F:F,"Paid Search") -> 0.0625 | P22: Basic | Q22: =COUNTIFS(experiment_data!C:C,"Control",experiment_data!G:G,"Basic",experiment_data!K:K,1)/COUNTIFS(experiment_data!C:C,"Control",experiment_data!G:G,"Basic") -> 0.036199095 | R22: =COUNTIFS(experiment_data!C:C,"Treatment",experiment_data!G:G,"Basic",experiment_data!K:K,1)/COUNTIFS(experiment_data!C:C,"Treatment",experiment_data!G:G,"Basic") -> 0.038793103
A23: East | B23: =COUNTIFS(experiment_data!C:C,"Control",experiment_data!D:D,"East",experiment_data!K:K,1)/COUNTIFS(experiment_data!C:C,"Control",experiment_data!D:D,"East") -> 0.025477707 | C23: =COUNTIFS(experiment_data!C:C,"Treatment",experiment_data!D:D,"East",experiment_data!K:K,1)/COUNTIFS(experiment_data!C:C,"Treatment",experiment_data!D:D,"East") -> 0.064705882 | F23: Tablet | G23: =COUNTIFS(experiment_data!C:C,"Control",experiment_data!E:E,"Tablet",experiment_data!K:K,1)/COUNTIFS(experiment_data!C:C,"Control",experiment_data!E:E,"Tablet") -> 0.018181818 | H23: =COUNTIFS(experiment_data!C:C,"Treatment",experiment_data!E:E,"Tablet",experiment_data!K:K,1)/COUNTIFS(experiment_data!C:C,"Treatment",experiment_data!E:E,"Tablet") -> 0.071428571 | K23: Social | L23: =COUNTIFS(experiment_data!C:C,"Control",experiment_data!F:F,"Social",experiment_data!K:K,1)/COUNTIFS(experiment_data!C:C,"Control",experiment_data!F:F,"Social") -> 0.07751938 | M23: =COUNTIFS(experiment_data!C:C,"Treatment",experiment_data!F:F,"Social",experiment_data!K:K,1)/COUNTIFS(experiment_data!C:C,"Treatment",experiment_data!F:F,"Social") -> 0.060606061 | P23: Premium | Q23: =COUNTIFS(experiment_data!C:C,"Control",experiment_data!G:G,"Premium",experiment_data!K:K,1)/COUNTIFS(experiment_data!C:C,"Control",experiment_data!G:G,"Premium") -> 0.027522936 | R23: =COUNTIFS(experiment_data!C:C,"Treatment",experiment_data!G:G,"Premium",experiment_data!K:K,1)/COUNTIFS(experiment_data!C:C,"Treatment",experiment_data!G:G,"Premium") -> 0.0625
A24: West | B24: =COUNTIFS(experiment_data!C:C,"Control",experiment_data!D:D,"West",experiment_data!K:K,1)/COUNTIFS(experiment_data!C:C,"Control",experiment_data!D:D,"West") -> 0.033783784 | C24: =COUNTIFS(experiment_data!C:C,"Treatment",experiment_data!D:D,"West",experiment_data!K:K,1)/COUNTIFS(experiment_data!C:C,"Treatment",experiment_data!D:D,"West") -> 0.050847458 | K24: Referral | L24: =COUNTIFS(experiment_data!C:C,"Control",experiment_data!F:F,"Referral",experiment_data!K:K,1)/COUNTIFS(experiment_data!C:C,"Control",experiment_data!F:F,"Referral") -> 0.024691358 | M24: =COUNTIFS(experiment_data!C:C,"Treatment",experiment_data!F:F,"Referral",experiment_data!K:K,1)/COUNTIFS(experiment_data!C:C,"Treatment",experiment_data!F:F,"Referral") -> 0.10989011
K25: Email | L25: =COUNTIFS(experiment_data!C:C,"Control",experiment_data!F:F,"Email",experiment_data!K:K,1)/COUNTIFS(experiment_data!C:C,"Control",experiment_data!F:F,"Email") -> 0.02739726 | M25: =COUNTIFS(experiment_data!C:C,"Treatment",experiment_data!F:F,"Email",experiment_data!K:K,1)/COUNTIFS(experiment_data!C:C,"Treatment",experiment_data!F:F,"Email") -> 0.071428571

Sheet hypothesis_test
A1: A/B Test — Paid Conversion Rate (Treatment vs Control)
A5: t-Test: Two-Sample Assuming Unequal Variances
B7: control_converted | C7: treatment_converted
A8: Mean | B8: 0.031884058 | C8: 0.070422535
A9: Variance | B9: 0.030912265 | C9: 0.065555533
A10: Observations | B10: 690 | C10: 710
A11: Hypothesized Mean Difference | B11: 0
A12: df | B12: 1259
A13: t Stat | B13: -3.2909778
A14: P(T<=t) one-tail | B14: 0.00051303098
A15: t Critical one-tail | B15: 1.6460648
A16: P(T<=t) two-tail | B16: 0.001026062
A17: t Critical two-tail | B17: 1.96185
